Workbook
Name NativeTimeline_Date: #N/A
Name Slicer_Category1: #N/A
Name Slicer_Customer_Segment1: #N/A
Name Slicer_Region: #N/A

Sheet Dashboard
A1: Data Intelligence Dashboard
G5: KPI Indicators
G6: KPI | H6: Actual | I6: Target | J6: Status
G7: Total Revenue | H7: =SUM('Raw data'!N2:N251) -> 229192.47 | I7: 200000 | J7: =IF(H7>=I7,"✅ On Target","❌ Below Target") -> ✅ On Target
G8: Average Order Value | H8: =AVERAGE('Raw data'!N2:N251) -> 916.76988 | I8: 800 | J8: =IF(H8>=I8,"✅ On Target","❌ Below Target") -> ✅ On Target
G9: Total Transactions | H9: =COUNTA('Raw data'!A2:A251) -> 250 | I9: 200 | J9: =IF(H9>=I9,"✅ On Target","❌ Below Target") -> ✅ On Target
G10: Unique Customers | H10: =COUNTA(_xlfn.UNIQUE('Raw data'!C2:C251)) -> 50 | I10: 45 | J10: =IF(H10>=I10,"✅ On Target","❌ Below Target") -> ✅ On Target
A39: Region | B39: Sum of Total_Amount | D39: Revenue by category | G39: Customer_Name | H39: Sum of Total_Amount
A40: Central | B40: 41288.34 | D40: Category | E40: Sum of Total_Amount | G40: Barbara Young | H40: 10649.8
A41: East | B41: 59288.39 | D41: Appliances | E41: 8338.74 | G41: Daniel King | H41: 7309.8
A42: North | B42: 50808.31 | D42: Electronics | E42: 171756.05 | G42: Dorothy Nelson | H42: 8269.79
A43: South | B43: 36398.75 | D43: Furniture | E43: 49097.68 | G43: Edward Mitchell | H43: 11919.77
A44: West | B44: 41408.68 | D44: Grand Total | E44: 229192.47 | G44: Joseph Jackson | H44: 6949.84
A45: Grand Total | B45: 229192.47 | G45: Karen Hill | H45: 8009.77
G46: Lawrence Reed | H46: 6989.77
G47: Mark Carter | H47: 15659.65
G48: Patricia Moore | H48: 9799.73
G49: Paul Baker | H49: 8309.74
G50: Grand Total | H50: 93867.66

Sheet Analysis
A1: Date & time Functions
A2: Today's date | B2: =TODAY() -> 46159
A3: Current date & time | B3: =NOW() -> 46159.602
A4: Days since first transaction in dataset | B4: =DATEDIF(MIN('Raw data'!B2:B251),TODAY(),"D") -> 766
A5: Last day of current month | B5: =EOMONTH(TODAY(),0) -> 46173
A7: Key summary metrics
A8: Total revenue | B8: =SUM('Raw data'!N:N) -> 229192.47
A9: Total transaction | B9: =COUNTA('Raw data'!A:A) -> 251
A10: Average order value | B10: =AVERAGE('Raw data'!N:N) -> 916.76988
A11: Unique customers | B11: {=SUMPRODUCT(1/COUNTIF('Raw data'!C2:C251,'Raw data'!C2:C251))} -> 50
A13: Most frequently purchased product | B13: {=INDEX('Raw data'!F2:F251, MATCH(MAX(COUNTIF('Raw data'!F2:F251,'Raw data'!F2:F251)), COUNTIF('Raw data'!F2:F251,'Raw data'!F2:F251), 0))} -> Bookshelf
A15: High value customers
A16: {=_xlfn.UNIQUE('Raw data'!D:D)} -> Customer_Name | B16: Total spent | C16: Segment
A17: Paul Baker | B17: =SUMIF('Raw data'!D:D,Analysis!A17,'Raw data'!N:N) -> 8309.74 | C17: =IF(B17>5000,"High value","Regular") -> High value
A18: Joseph Jackson | B18: =SUMIF('Raw data'!D:D,Analysis!A18,'Raw data'!N:N) -> 6949.84 | C18: =IF(B18>5000,"High value","Regular") -> High value
A19: Kevin Scott | B19: =SUMIF('Raw data'!D:D,Analysis!A19,'Raw data'!N:N) -> 3259.87 | C19: =IF(B19>5000,"High value","Regular") -> Regular
A20: Kathleen Bennett | B20: =SUMIF('Raw data'!D:D,Analysis!A20,'Raw data'!N:N) -> 4309.81 | C20: =IF(B20>5000,"High value","Regular") -> Regular
A21: Michael Brown | B21: =SUMIF('Raw data'!D:D,Analysis!A21,'Raw data'!N:N) -> 6169.74 | C21: =IF(B21>5000,"High value","Regular") -> High value
A22: Dorothy Nelson | B22: =SUMIF('Raw data'!D:D,Analysis!A22,'Raw data'!N:N) -> 8269.79 | C22: =IF(B22>5000,"High value","Regular") -> High value
A23: Charles Allen | B23: =SUMIF('Raw data'!D:D,Analysis!A23,'Raw data'!N:N) -> 5089.73 | C23: =IF(B23>5000,"High value","Regular") -> High value
A24: Robert Thomas | B24: =SUMIF('Raw data'!D:D,Analysis!A24,'Raw data'!N:N) -> 3509.9 | C24: =IF(B24>5000,"High value","Regular") -> Regular
A25: Karen Hill | B25: =SUMIF('Raw data'!D:D,Analysis!A25,'Raw data'!N:N) -> 8009.77 | C25: =IF(B25>5000,"High value","Regular") -> High value
A26: Susan Green | B26: =SUMIF('Raw data'!D:D,Analysis!A26,'Raw data'!N:N) -> 1979.89 | C26: =IF(B26>5000,"High value","Regular") -> Regular
A27: Peter Richardson | B27: =SUMIF('Raw data'!D:D,Analysis!A27,'Raw data'!N:N) -> 5949.85 | C27: =IF(B27>5000,"High value","Regular") -> High value
A28: Dennis Gray | B28: =SUMIF('Raw data'!D:D,Analysis!A28,'Raw data'!N:N) -> 479.92 | C28: =IF(B28>5000,"High value","Regular") -> Regular
... A66: John Smith | B66: =SUMIF('Raw data'!D:D,Analysis!A66,'Raw data'!N:N) -> 599.96 | C66: =IF(B66>5000,"High value","Regular") -> Regular
A67: 0
A69: Filter function
A70: Premium segment customers
A71: {=_xlfn._xlws.FILTER('Raw data'!A2:P251,'Raw data'!L2:L251="Premium")} -> TRX0023 | B71: 45396 | C71: CUST013 | D71: Joseph Jackson | E71: P009 | F71: Monitor | G71: Electronics | H71: 3 | I71: 249.99 | J71: Credit Card | K71: Central | L71: Premium | M71: 44575 | N71: 749.97 | O71: 1584 | P71: 763
A72: TRX0043 | B72: 45400 | C72: CUST046 | D72: Kathleen Bennett | E72: P005 | F72: Blender | G72: Appliances | H72: 3 | I72: 59.99 | J72: Cash | K72: North | L72: Premium | M72: 45114 | N72: 179.97 | O72: 1045 | P72: 759
A73: TRX0212 | B73: 45400 | C73: CUST003 | D73: Michael Brown | E73: P008 | F73: Bookshelf | G73: Furniture | H73: 5 | I73: 149.99 | J73: Credit Card | K73: North | L73: Premium | M73: 45295 | N73: 749.95 | O73: 864 | P73: 759
A74: TRX0185 | B74: 45408 | C74: CUST026 | D74: Karen Hill | E74: P005 | F74: Blender | G74: Appliances | H74: 3 | I74: 59.99 | J74: Cash | K74: West | L74: Premium | M74: 45207 | N74: 179.97 | O74: 952 | P74: 751
A75: TRX0246 | B75: 45408 | C75: CUST041 | D75: Peter Richardson | E75: P008 | F75: Bookshelf | G75: Furniture | H75: 3 | I75: 149.99 | J75: Cash | K75: North | L75: Premium | M75: 44806 | N75: 449.97 | O75: 1353 | P75: 751
A76: TRX0049 | B76: 45410 | C76: CUST025 | D76: Mark Carter | E76: P008 | F76: Bookshelf | G76: Furniture | H76: 4 | I76: 149.99 | J76: Debit Card | K76: North | L76: Premium | M76: 45374 | N76: 599.96 | O76: 785 | P76: 749
A77: TRX0222 | B77: 45410 | C77: CUST048 | D77: Virginia Sanders | E77: P009 | F77: Monitor | G77: Electronics | H77: 3 | I77: 249.99 | J77: Credit Card | K77: North | L77: Premium | M77: 45224 | N77: 749.97 | O77: 935 | P77: 749
A78: TRX0242 | B78: 45416 | C78: CUST025 | D78: Mark Carter | E78: P007 | F78: Desk | G78: Furniture | H78: 4 | I78: 299.99 | J78: Cash | K78: West | L78: Premium | M78: 44716 | N78: 1199.96 | O78: 1443 | P78: 743
A79: TRX0235 | B79: 45424 | C79: CUST014 | D79: Linda Martin | E79: P004 | F79: Coffee Maker | G79: Appliances | H79: 3 | I79: 79.99 | J79: PayPal | K79: East | L79: Premium | M79: 45012 | N79: 239.97 | O79: 1147 | P79: 735
A80: TRX0004 | B80: 45424 | C80: CUST012 | D80: Patricia Moore | E80: P010 | F80: Keyboard | G80: Electronics | H80: 5 | I80: 89.99 | J80: Cash | K80: North | L80: Premium | M80: 44919 | N80: 449.95 | O80: 1240 | P80: 735
A81: TRX0130 | B81: 45430 | C81: CUST002 | D81: Emma Wilson | E81: P008 | F81: Bookshelf | G81: Furniture | H81: 3 | I81: 149.99 | J81: Credit Card | K81: West | L81: Premium | M81: 45068 | N81: 449.97 | O81: 1091 | P81: 729
...

Sheet what-if
A1: What if analysis
A3: Scenario manager
A4: Unit price | B4: 599
A5: Quantity | B5: 10
A6: Discount(%) | B6: 0.2
A7: Projected revenue | B7: =B4*B5*(1-B6) -> 4792
A11: Goal seek
A12: Unit price | B12: 500
A13: Quantity needed | B13: 1112
A14: Discount(%) | B14: 0.1
A15: Target revenue | B15: 50000
A16: Projected revenue | B16: =B12*B13*(1-B14) -> 500400

Sheet Scenario Summary
B2: Scenario Summary
D3: Current Values: | E3: Best case | F3: Base case | G3: Worst case
B5: Changing Cells:
C6: $B$4 | D6: 599 | E6: 1100 | F6: 899 | G6: 599
C7: $B$5 | D7: 5 | E7: 20 | F7: 10 | G7: 5
C8: $B$6 | D8: 0.2 | E8: 0.1 | F8: 0.1 | G8: 0.2
B9: Result Cells:
C10: $B$7 | D10: 2396 | E10: 19800 | F10: 8091 | G10: 2396
B11: Notes: Current Values column represents values of changing cells at
B12: time Scenario Summary Report was created. Changing cells for each
B13: scenario are highlighted in gray.

Sheet Regression
A1: SUMMARY OUTPUT
A3: Regression Statistics
A4: Multiple R | B4: 0.83544893
A5: R Square | B5: 0.69797492
A6: Adjusted R Square | B6: 0.69675708
A7: Standard Error | B7: 568.54608
A8: Observations | B8: 250
A10: ANOVA
B11: df | C11: SS | D11: MS | E11: F | F11: Significance F
A12: Regression | B12: 1 | C12: 1.8525922e+08 | D12: 1.8525922e+08 | E12: 573.12386 | F12: 2.0274088e-66
A13: Residual | B13: 248 | C13: 80164673 | D13: 323244.65
A14: Total | B14: 249 | C14: 2.6542389e+08
B16: Coefficients | C16: Standard Error | D16: t Stat | E16: P-value | F16: Lower 95% | G16: Upper 95% | H16: Lower 95.0% | I16: Upper 95.0%
A17: Intercept | B17: -14.342533 | C17: 52.968753 | D17: -0.27077347 | E17: 0.78679049 | F17: -118.6685 | G17: 89.983434 | H17: -118.6685 | I17: 89.983434
A18: X Variable 1 | B18: 3.1385459 | C18: 0.13110047 | D18: 23.940005 | E18: 2.0274088e-66 | F18: 2.8803336 | G18: 3.3967582 | H18: 2.8803336 | I18: 3.3967582

Sheet Visualizations
A1: Revenue by region
A2: Region | B2: Sum of Total_Amount
A3: Central | B3: 41288.34
A4: East | B4: 59288.39
A5: North | B5: 50808.31
A6: South | B6: 36398.75
A7: West | B7: 41408.68
A8: Grand Total | B8: 229192.47
A16: Monthly revenue
A17: Month-Year | B17: Sum of Total_Amount
A18: 2024-04 | B18: 20919.33
A19: 2024-05 | B19: 17039.35
A20: 2024-06 | B20: 19299.45
A21: 2024-07 | B21: 18479.4
A22: 2024-08 | B22: 15759.43
A23: 2024-09 | B23: 12989.51
A24: 2024-10 | B24: 20609.52
A25: 2024-11 | B25: 12309.44
A26: 2024-12 | B26: 23039.3
A27: 2025-01 | B27: 25799.15
A28: 2025-02 | B28: 16069.38
A29: 2025-03 | B29: 19899.38
... A31: Grand Total | B31: 229192.47
A38: Revenue by category
A39: Category | B39: Sum of Total_Amount
A40: Appliances | B40: 8338.74
A41: Electronics | B41: 171756.05
A42: Furniture | B42: 49097.68
A43: Grand Total | B43: 229192.47

Sheet Insights
A1: Data Intelligence Dashboard — Final Report & Insights
A3: Key Metrics Summary
B4: Total Revenue | C4: =SUM('Raw data'!N2:N251) -> 229192.47
B5: Total Transactions | C5: =COUNTA('Raw data'!A2:A251) -> 250
B6: Average Order Value | C6: =AVERAGE('Raw data'!N2:N251) -> 916.76988
B7: Unique Customers | C7: =COUNTA(_xlfn.UNIQUE('Raw data'!C2:C251)) -> 50
B8: Most Sold Product | C8: {=INDEX('Raw data'!F2:F251,MATCH(MAX(COUNTIF('Raw data'!F2:F251,'Raw data'!F2:F251)),COUNTIF('Raw data'!F2:F251,'Raw data'!F2:F251),0))} -> Bookshelf
A10: Regional Sales Analysis
B11: Region | C11: Total Revenue | D11: % of Total
B12: Central | C12: =SUMIF('Raw data'!K:K,"Central",'Raw data'!N:N) -> 41288.34 | D12: =C12/SUM($C$12:$C$16)*100 -> 18.014702
B13: East | C13: =SUMIF('Raw data'!K:K,"East",'Raw data'!N:N) -> 59288.39 | D13: =C13/SUM($C$12:$C$16)*100 -> 25.868385
B14: North | C14: =SUMIF('Raw data'!K:K,"North",'Raw data'!N:N) -> 50808.31 | D14: =C14/SUM($C$12:$C$16)*100 -> 22.168403
B15: South | C15: =SUMIF('Raw data'!K:K,"South",'Raw data'!N:N) -> 36398.75 | D15: =C15/SUM($C$12:$C$16)*100 -> 15.881303
B16: West | C16: =SUMIF('Raw data'!K:K,"West",'Raw data'!N:N) -> 41408.68 | D16: =C16/SUM($C$12:$C$16)*100 -> 18.067208
A18: Key Business Insights & Storytelling
A19: 1 | B19: East region generates highest revenue at ₹59,288 — contributing 25.9% of total revenue
A20: 2 | B20: Electronics is the top performing category with ₹1,71,756 revenue — 75% of total sales
A21: 3 | B21: Mark Carter is the highest spending customer with ₹15,659 in total purchases
A22: 4 | B22: Bookshelf is the most frequently purchased product across all transactions
A23: 5 | B23: Average order value of ₹916.77 suggests customers prefer mid to high range products
A24: 6 | B24: Regression analysis shows Unit Price explains 69.8% of revenue variation — strong predictor
A25: 7 | B25: Premium segment customers account for majority of high value transactions
A26: 8 | B26: Goal Seek analysis shows 1112 units needed to achieve ₹50,000 revenue target

Sheet Raw data
A1: Transaction_ID | B1: Date | C1: Customer_ID | D1: Customer_Name | E1: Product_ID | F1: Product_Name | G1: Category | H1: Quantity | I1: Unit_Price | J1: Payment_Method | K1: Region | L1: Customer_Segment | M1: Customer_Since | N1: Total_Amount | O1: Days as customer | P1: Transaction days | Q1: Month-Year | R1: Short date
A2: TRX0155 | B2: 45393 | C2: CUST023 | D2: Paul Baker | E2: P009 | F2: Monitor | G2: Electronics | H2: 3 | I2: 249.99 | J2: Cash | K2: Central | L2: Basic | M2: 44425 | N2: 749.97 | O2: =TODAY()-M2 -> 1734 | P2: =TODAY()-B2 -> 766 | Q2: =TEXT(B2,"yyyy-mm") -> 2024-04 | R2: =YEAR(B2)*100+MONTH(B2) -> 202404
A3: TRX0023 | B3: 45396 | C3: CUST013 | D3: Joseph Jackson | E3: P009 | F3: Monitor | G3: Electronics | H3: 3 | I3: 249.99 | J3: Credit Card | K3: Central | L3: Premium | M3: 44575 | N3: 749.97 | O3: =TODAY()-M3 -> 1584 | P3: =TODAY()-B3 -> 763 | Q3: =TEXT(B3,"yyyy-mm") -> 2024-04 | R3: =YEAR(B3)*100+MONTH(B3) -> 202404
A4: TRX0139 | B4: 45399 | C4: CUST021 | D4: Kevin Scott | E4: P005 | F4: Blender | G4: Appliances | H4: 3 | I4: 59.99 | J4: PayPal | K4: South | L4: Standard | M4: 45262 | N4: 179.97 | O4: =TODAY()-M4 -> 897 | P4: =TODAY()-B4 -> 760 | Q4: =TEXT(B4,"yyyy-mm") -> 2024-04 | R4: =YEAR(B4)*100+MONTH(B4) -> 202404
A5: TRX0043 | B5: 45400 | C5: CUST046 | D5: Kathleen Bennett | E5: P005 | F5: Blender | G5: Appliances | H5: 3 | I5: 59.99 | J5: Cash | K5: North | L5: Premium | M5: 45114 | N5: 179.97 | O5: =TODAY()-M5 -> 1045 | P5: =TODAY()-B5 -> 759 | Q5: =TEXT(B5,"yyyy-mm") -> 2024-04 | R5: =YEAR(B5)*100+MONTH(B5) -> 202404
A6: TRX0212 | B6: 45400 | C6: CUST003 | D6: Michael Brown | E6: P008 | F6: Bookshelf | G6: Furniture | H6: 5 | I6: 149.99 | J6: Credit Card | K6: North | L6: Premium | M6: 45295 | N6: 749.95 | O6: =TODAY()-M6 -> 864 | P6: =TODAY()-B6 -> 759 | Q6: =TEXT(B6,"yyyy-mm") -> 2024-04 | R6: =YEAR(B6)*100+MONTH(B6) -> 202404
A7: TRX0092 | B7: 45403 | C7: CUST024 | D7: Dorothy Nelson | E7: P005 | F7: Blender | G7: Appliances | H7: 2 | I7: 59.99 | J7: Cash | K7: West | L7: Standard | M7: 44746 | N7: 119.98 | O7: =TODAY()-M7 -> 1413 | P7: =TODAY()-B7 -> 756 | Q7: =TEXT(B7,"yyyy-mm") -> 2024-04 | R7: =YEAR(B7)*100+MONTH(B7) -> 202404
A8: TRX0193 | B8: 45403 | C8: CUST024 | D8: Dorothy Nelson | E8: P003 | F8: Headphones | G8: Electronics | H8: 5 | I8: 149.99 | J8: Credit Card | K8: Central | L8: Standard | M8: 44418 | N8: 749.95 | O8: =TODAY()-M8 -> 1741 | P8: =TODAY()-B8 -> 756 | Q8: =TEXT(B8,"yyyy-mm") -> 2024-04 | R8: =YEAR(B8)*100+MONTH(B8) -> 202404
A9: TRX0240 | B9: 45403 | C9: CUST017 | D9: Charles Allen | E9: P005 | F9: Blender | G9: Appliances | H9: 3 | I9: 59.99 | J9: Debit Card | K9: South | L9: Basic | M9: 45007 | N9: 179.97 | O9: =TODAY()-M9 -> 1152 | P9: =TODAY()-B9 -> 756 | Q9: =TEXT(B9,"yyyy-mm") -> 2024-04 | R9: =YEAR(B9)*100+MONTH(B9) -> 202404
A10: TRX0135 | B10: 45405 | C10: CUST009 | D10: Robert Thomas | E10: P001 | F10: Laptop | G10: Electronics | H10: 3 | I10: 899.99 | J10: PayPal | K10: East | L10: Standard | M10: 45299 | N10: 2699.97 | O10: =TODAY()-M10 -> 860 | P10: =TODAY()-B10 -> 754 | Q10: =TEXT(B10,"yyyy-mm") -> 2024-04 | R10: =YEAR(B10)*100+MONTH(B10) -> 202404
A11: TRX0185 | B11: 45408 | C11: CUST026 | D11: Karen Hill | E11: P005 | F11: Blender | G11: Appliances | H11: 3 | I11: 59.99 | J11: Cash | K11: West | L11: Premium | M11: 45207 | N11: 179.97 | O11: =TODAY()-M11 -> 952 | P11: =TODAY()-B11 -> 751 | Q11: =TEXT(B11,"yyyy-mm") -> 2024-04 | R11: =YEAR(B11)*100+MONTH(B11) -> 202404
A12: TRX0138 | B12: 45408 | C12: CUST022 | D12: Susan Green | E12: P008 | F12: Bookshelf | G12: Furniture | H12: 1 | I12: 149.99 | J12: Credit Card | K12: West | L12: Standard | M12: 45103 | N12: 149.99 | O12: =TODAY()-M12 -> 1056 | P12: =TODAY()-B12 -> 751 | Q12: =TEXT(B12,"yyyy-mm") -> 2024-04 | R12: =YEAR(B12)*100+MONTH(B12) -> 202404
A13: TRX0209 | B13: 45408 | C13: CUST046 | D13: Kathleen Bennett | E13: P008 | F13: Bookshelf | G13: Furniture | H13: 5 | I13: 149.99 | J13: Debit Card | K13: North | L13: Basic | M13: 44830 | N13: 749.95 | O13: =TODAY()-M13 -> 1329 | P13: =TODAY()-B13 -> 751 | Q13: =TEXT(B13,"yyyy-mm") -> 2024-04 | R13: =YEAR(B13)*100+MONTH(B13) -> 202404
... A251: TRX0064 | B251: 45758 | C251: CUST031 | D251: Steven Turner | E251: P010 | F251: Keyboard | G251: Electronics | H251: 3 | I251: 89.99 | J251: Debit Card | K251: North | L251: Premium | M251: 44878 | N251: 269.97 | O251: =TODAY()-M251 -> 1281 | P251: =TODAY()-B251 -> 401 | Q251: =TEXT(B251,"yyyy-mm") -> 2025-04 | R251: =YEAR(B251)*100+MONTH(B251) -> 202504
